<?xml version="1.0" ?>
<!-- =================================================================================== -->
<!-- |    This document was autogenerated by xacro from /tmp/ufactory_vendor_trmkc07j/bio/gen.urdf.xacro | -->
<!-- |    EDITING THIS FILE BY HAND IS NOT RECOMMENDED                                 | -->
<!-- =================================================================================== -->
<robot name="bio_gripper">
  <material name="Black">
    <color rgba="0.0 0.0 0.0 1.0"/>
  </material>
  <material name="Red">
    <color rgba="0.8 0.0 0.0 1.0"/>
  </material>
  <material name="White">
    <color rgba="1.0 1.0 1.0 1.0"/>
  </material>
  <material name="Silver">
    <color rgba="0.753 0.753 0.753 1.0"/>
  </material>
  <joint name="bio_gripper_fix" type="fixed">
    <parent link="link_tool"/>
    <child link="bio_gripper_base_link"/>
    <origin rpy="0 0 0" xyz="0 0 0"/>
  </joint>
  <link name="bio_gripper_base_link">
    <inertial>
      <origin rpy="0 0 0" xyz="0.016179 -2.3911E-05 0.023897"/>
      <mass value="0.38837"/>
      <inertia ixx="0.00088398" ixy="4.8665E-08" ixz="5.6276E-06" iyy="0.00018256" iyz="4.0828E-08" izz="0.00094673"/>
    </inertial>
    <visual>
      <geometry>
        <mesh filename="meshes/gripper/bio/link_base.stl"/>
      </geometry>
      <origin rpy="0 0 0" xyz="0 0 0"/>
      <material name="White"/>
    </visual>
    <collision>
      <geometry>
        <mesh filename="meshes/gripper/bio/link_base.stl"/>
      </geometry>
      <origin rpy="0 0 0" xyz="0 0 0"/>
    </collision>
  </link>
  <link name="bio_gripper_left_finger">
    <inertial>
      <origin rpy="0 0 0" xyz="0.021846 -0.0276 0.011911"/>
      <mass value="0.012105"/>
      <inertia ixx="3.7322E-06" ixy="4.1705E-06" ixz="-4.0142E-06" iyy="1.744E-05" iyz="1.2237E-06" izz="1.7775E-05"/>
    </inertial>
    <visual>
      <geometry>
        <mesh filename="meshes/gripper/bio/left_finger.stl"/>
      </geometry>
      <origin rpy="0 0 0" xyz="0 0 0"/>
      <material name="White"/>
    </visual>
    <collision>
      <geometry>
        <mesh filename="meshes/gripper/bio/left_finger.stl"/>
      </geometry>
      <origin rpy="0 0 0" xyz="0 0 0"/>
    </collision>
  </link>
  <joint name="left_finger_joint" type="prismatic">
    <origin rpy="0 0 0" xyz="0.059 0 0.027"/>
    <parent link="bio_gripper_base_link"/>
    <child link="bio_gripper_left_finger"/>
    <axis xyz="0 1 0"/>
    <limit effort="2.0" lower="-0.04" upper="0.0" velocity="0.1"/>
    <mimic joint="right_finger_joint" multiplier="-1" offset="0"/>
  </joint>
  <link name="bio_gripper_right_finger">
    <inertial>
      <origin rpy="0 0 0" xyz="0.02037 0.027565 0.010274"/>
      <mass value="0.012068"/>
      <inertia ixx="4.1413E-06" ixy="-3.9682E-06" ixz="-4.5734E-06" iyy="1.6115E-05" iyz="-1.6711E-06" izz="1.6032E-05"/>
    </inertial>
    <visual>
      <geometry>
        <mesh filename="meshes/gripper/bio/right_finger.stl"/>
      </geometry>
      <origin rpy="0 0 0" xyz="0 0 0"/>
      <material name="White"/>
    </visual>
    <collision>
      <geometry>
        <mesh filename="meshes/gripper/bio/right_finger.stl"/>
      </geometry>
      <origin rpy="0 0 0" xyz="0 0 0"/>
    </collision>
  </link>
  <joint name="right_finger_joint" type="prismatic">
    <origin rpy="0 0 0" xyz="0.059 0 0.027"/>
    <parent link="bio_gripper_base_link"/>
    <child link="bio_gripper_right_finger"/>
    <axis xyz="0 1 0"/>
    <limit effort="2.0" lower="0" upper="0.04" velocity="0.1"/>
  </joint>
  <link name="link_tcp"/>
  <joint name="joint_tcp" type="fixed">
    <origin rpy="0 0 0" xyz="0.135 0 0.055"/>
    <parent link="bio_gripper_base_link"/>
    <child link="link_tcp"/>
  </joint>
</robot>
