<?xml version='1.0' encoding='utf-8'?>
<robot name="gripper_g2">
  <link name="link_tool" />
  <joint name="gripper_attach" type="fixed">
    <parent link="link_tool" />
    <child link="xarm_gripper_base_link" />
    <origin xyz="0 0 0" rpy="0 0 0" />
  </joint>
  <link name="xarm_gripper_base_link">
    <inertial>
      <origin xyz="-0.00065489 -0.0018497 0.048028" rpy="0 0 0" />
      <mass value="0.54156" />
      <inertia ixx="0.00047106" ixy="3.9292e-07" ixz="2.6537e-06" iyy="0.00033072" iyz="-1.0975e-05" izz="0.00025642" />
    </inertial>
    <visual>
      <origin xyz="0 0 0" rpy="0 0 0" />
      <geometry>
        <mesh filename="meshes/collision/base_link.STL" />
      </geometry>
      <material name="White" />
    </visual>
    <collision>
      <origin xyz="0 0 0" rpy="0 0 0" />
      <geometry>
        <mesh filename="meshes/collision/base_link.STL" />
      </geometry>
    </collision>
  </link>
  <joint name="gripper_fix" type="fixed">
    <parent link="link_eef" />
    <child link="xarm_gripper_base_link" />
    <origin xyz="0 0 0" rpy="0 0 0" />
  </joint>
  <link name="left_outer_knuckle">
    <inertial>
      <origin xyz="0 0.01175 0.02625" rpy="0 0 0" />
      <mass value="0.033618" />
      <inertia ixx="1.9111e-05" ixy="0" ixz="0" iyy="6.6256e-06" iyz="-7.3008e-06" izz="1.3185e-05" />
    </inertial>
    <visual>
      <origin xyz="0 0 0" rpy="0 0 0" />
      <geometry>
        <mesh filename="meshes/collision/left_outer_knuckle.STL" />
      </geometry>
      <material name="Silver" />
    </visual>
    <collision>
      <origin xyz="0 0 0" rpy="0 0 0" />
      <geometry>
        <mesh filename="meshes/collision/left_outer_knuckle.STL" />
      </geometry>
    </collision>
  </link>
  <joint name="drive_joint" type="revolute">
    <parent link="xarm_gripper_base_link" />
    <child link="left_outer_knuckle" />
    <origin xyz="0 0.035 0.059098" rpy="0 0 0" />
    <axis xyz="1 0 0" />
    <limit lower="0" upper="0.85" effort="50" velocity="2" />
    <dynamics damping="1.0" friction="0.5" />
  </joint>
  <link name="left_finger">
    <inertial>
      <origin xyz="0 -0.01425 0.03" rpy="0 0 0" />
      <mass value="0.048304" />
      <inertia ixx="1.7493e-05" ixy="0" ixz="0" iyy="1.7225e-05" iyz="4.6433e-06" izz="5.1466e-06" />
    </inertial>
    <visual>
      <origin xyz="0 0 0" rpy="0 0 0" />
      <geometry>
        <mesh filename="meshes/collision/left_finger.STL" />
      </geometry>
      <material name="Silver" />
    </visual>
    <collision>
      <origin xyz="0 0 0" rpy="0 0 0" />
      <geometry>
        <mesh filename="meshes/collision/left_finger.STL" />
      </geometry>
    </collision>
  </link>
  <joint name="left_finger_joint" type="revolute">
    <parent link="left_outer_knuckle" />
    <child link="left_finger" />
    <origin xyz="0 0.035465 0.042039" rpy="0 0 0" />
    <axis xyz="-1 0 0" />
    <limit lower="0" upper="0.85" effort="50" velocity="2" />
    <dynamics damping="1.0" friction="0.5" />
    <mimic joint="drive_joint" multiplier="1" offset="0" />
  </joint>
  <link name="left_inner_knuckle">
    <inertial>
      <origin xyz="0 0.011 0.035" rpy="0 0 0" />
      <mass value="0.023013" />
      <inertia ixx="6.0949e-06" ixy="0" ixz="0" iyy="6.0196e-06" iyz="-2.7532e-06" izz="5.0786e-06" />
    </inertial>
    <visual>
      <origin xyz="0 0 0" rpy="0 0 0" />
      <geometry>
        <mesh filename="meshes/collision/left_inner_knuckle.STL" />
      </geometry>
      <material name="Silver" />
    </visual>
    <collision>
      <origin xyz="0 0 0" rpy="0 0 0" />
      <geometry>
        <mesh filename="meshes/collision/left_inner_knuckle.STL" />
      </geometry>
    </collision>
  </link>
  <joint name="left_inner_knuckle_joint" type="revolute">
    <parent link="xarm_gripper_base_link" />
    <child link="left_inner_knuckle" />
    <origin xyz="0 0.02 0.074098" rpy="0 0 0" />
    <axis xyz="1 0 0" />
    <limit lower="0" upper="0.85" effort="50" velocity="2" />
    <dynamics damping="1.0" friction="0.5" />
    <mimic joint="drive_joint" multiplier="1" offset="0" />
  </joint>
  <link name="right_outer_knuckle">
    <inertial>
      <origin xyz="0 -0.01175 0.02625" rpy="0 0 0" />
      <mass value="0.033618" />
      <inertia ixx="1.9111e-05" ixy="0" ixz="0" iyy="6.6256e-06" iyz="7.3008e-06" izz="1.3185e-05" />
    </inertial>
    <visual>
      <origin xyz="0 0 0" rpy="0 0 0" />
      <geometry>
        <mesh filename="meshes/collision/right_outer_knuckle.STL" />
      </geometry>
      <material name="Silver" />
    </visual>
    <collision>
      <origin xyz="0 0 0" rpy="0 0 0" />
      <geometry>
        <mesh filename="meshes/collision/right_outer_knuckle.STL" />
      </geometry>
    </collision>
  </link>
  <joint name="right_outer_knuckle_joint" type="revolute">
    <parent link="xarm_gripper_base_link" />
    <child link="right_outer_knuckle" />
    <origin xyz="0 -0.035 0.059098" rpy="0 0 0" />
    <axis xyz="-1 0 0" />
    <limit lower="0" upper="0.85" effort="50" velocity="2" />
    <dynamics damping="1.0" friction="0.5" />
    <mimic joint="drive_joint" multiplier="1" offset="0" />
  </joint>
  <link name="right_finger">
    <inertial>
      <origin xyz="0 0.01425 0.03" rpy="0 0 0" />
      <mass value="0.048304" />
      <inertia ixx="1.7493e-05" ixy="0" ixz="0" iyy="1.7225e-05" iyz="-4.6435e-06" izz="5.1466e-06" />
    </inertial>
    <visual>
      <origin xyz="0 0 0" rpy="0 0 0" />
      <geometry>
        <mesh filename="meshes/collision/right_finger.STL" />
      </geometry>
      <material name="Silver" />
    </visual>
    <collision>
      <origin xyz="0 0 0" rpy="0 0 0" />
      <geometry>
        <mesh filename="meshes/collision/right_finger.STL" />
      </geometry>
    </collision>
  </link>
  <joint name="right_finger_joint" type="revolute">
    <parent link="right_outer_knuckle" />
    <child link="right_finger" />
    <origin xyz="0 -0.035465 0.042039" rpy="0 0 0" />
    <axis xyz="1 0 0" />
    <limit lower="0" upper="0.85" effort="50" velocity="2" />
    <dynamics damping="1.0" friction="0.5" />
    <mimic joint="drive_joint" multiplier="1" offset="0" />
  </joint>
  <link name="right_inner_knuckle">
    <inertial>
      <origin xyz="0 -0.011 0.035" rpy="0 0 0" />
      <mass value="0.023013" />
      <inertia ixx="6.0949e-06" ixy="0" ixz="0" iyy="6.0196e-06" iyz="2.7531e-06" izz="5.0784e-06" />
    </inertial>
    <visual>
      <origin xyz="0 0 0" rpy="0 0 0" />
      <geometry>
        <mesh filename="meshes/collision/right_inner_knuckle.STL" />
      </geometry>
      <material name="Silver" />
    </visual>
    <collision>
      <origin xyz="0 0 0" rpy="0 0 0" />
      <geometry>
        <mesh filename="meshes/collision/right_inner_knuckle.STL" />
      </geometry>
    </collision>
  </link>
  <joint name="right_inner_knuckle_joint" type="revolute">
    <parent link="xarm_gripper_base_link" />
    <child link="right_inner_knuckle" />
    <origin xyz="0 -0.02 0.074098" rpy="0 0 0" />
    <axis xyz="-1 0 0" />
    <limit lower="0" upper="0.85" effort="50" velocity="2" />
    <dynamics damping="1.0" friction="0.5" />
    <mimic joint="drive_joint" multiplier="1" offset="0" />
  </joint>
  <link name="link_tcp" />
  <joint name="joint_tcp" type="fixed">
    <parent link="xarm_gripper_base_link" />
    <child link="link_tcp" />
    <origin xyz="0 0 0.172" rpy="0 0 0" />
  </joint>
</robot>