<?xml version='1.0' encoding='utf-8'?>
<robot name="xarm5_1305_bio_gripper_g2_movable_visual.glb">
  <material name="Black">
    <color rgba="0.0 0.0 0.0 1.0" />
  </material>
  <material name="Red">
    <color rgba="0.8 0.0 0.0 1.0" />
  </material>
  <material name="White">
    <color rgba="1.0 1.0 1.0 1.0" />
  </material>
  <material name="Silver">
    <color rgba="0.753 0.753 0.753 1.0" />
  </material>
  <link name="world" />
  <joint name="world_joint" type="fixed">
    <parent link="world" />
    <child link="link_base" />
    <origin xyz="0 0 0" rpy="0 0 0" />
  </joint>
  <link name="link_base">
    <inertial>
      <origin rpy="0 0 0" xyz="-0.00218 -0.00023 0.08604" />
      <mass value="1.95" />
      <inertia ixx="0.004805" ixy="-8.33E-06" ixz="0.00026847" iyy="0.0050349" iyz="7.23E-06" izz="0.0025418" />
    </inertial>
    <visual>
      <geometry>
        <mesh filename="meshes/xarm5_1305/visual_glb/link_base.glb" />
      </geometry>
      <origin rpy="0 0 0" xyz="0 0 0" />
      <material name="White" />
    </visual>
    <collision>
      <geometry>
        <mesh filename="meshes/xarm5_1305/collision/link_base.obj" />
      </geometry>
      <origin rpy="0 0 0" xyz="0 0 0" />
    </collision>
  </link>
  <link name="link1">
    <inertial>
      <origin rpy="0 0 0" xyz="0.00013 0.0294 -0.01239" />
      <mass value="2.3849" />
      <inertia ixx="0.005705" ixy="1.056e-05" ixz="-2.642e-05" iyy="0.00489488" iyz="-0.000890795" izz="0.00334846" />
    </inertial>
    <visual>
      <geometry>
        <mesh filename="meshes/xarm5_1305/visual_glb/link1.glb" />
      </geometry>
      <origin rpy="0 0 0" xyz="0 0 0" />
      <material name="White" />
    </visual>
    <collision>
      <geometry>
        <mesh filename="meshes/xarm5_1305/collision/link1.obj" />
      </geometry>
      <origin rpy="0 0 0" xyz="0 0 0" />
    </collision>
  </link>
  <joint name="joint1" type="revolute">
    <origin rpy="0 0 0" xyz="0 0 0.267" />
    <parent link="link_base" />
    <child link="link1" />
    <axis xyz="0 0 1" />
    <limit effort="50" lower="-6.283185307179586" upper="6.283185307179586" velocity="3.14" />
    <dynamics damping="10" friction="1" />
  </joint>
  <link name="link2">
    <inertial>
      <origin rpy="0 0 0" xyz="0.03788 -0.2254 0.03447" />
      <mass value="2.164" />
      <inertia ixx="0.0278053" ixy="0.0048865" ixz="0.000656695" iyy="0.00551739" iyz="-0.00466808" izz="0.02692536" />
    </inertial>
    <visual>
      <geometry>
        <mesh filename="meshes/xarm5_1305/visual_glb/link2.glb" />
      </geometry>
      <origin rpy="0 0 0" xyz="0 0 0" />
      <material name="White" />
    </visual>
    <collision>
      <geometry>
        <mesh filename="meshes/xarm5_1305/collision/link2.obj" />
      </geometry>
      <origin rpy="0 0 0" xyz="0 0 0" />
    </collision>
  </link>
  <joint name="joint2" type="revolute">
    <origin rpy="-1.5708 0 0" xyz="0 0 0" />
    <parent link="link1" />
    <child link="link2" />
    <axis xyz="0 0 1" />
    <limit effort="50" lower="-2.059" upper="2.0944" velocity="3.14" />
    <dynamics damping="10" friction="1" />
  </joint>
  <link name="link3">
    <inertial>
      <origin rpy="0 0 0" xyz="0.06883 0.22985 0.00102" />
      <mass value="2.121" />
      <inertia ixx="0.0373639" ixy="-0.00417385" ixz="0.00143647" iyy="0.0058447" iyz="0.0075398" izz="0.0359236" />
    </inertial>
    <visual>
      <geometry>
        <mesh filename="meshes/xarm5_1305/visual_glb/link3.glb" />
      </geometry>
      <origin rpy="0 0 0" xyz="0 0 0" />
      <material name="White" />
    </visual>
    <collision>
      <geometry>
        <mesh filename="meshes/xarm5_1305/collision/link3.obj" />
      </geometry>
      <origin rpy="0 0 0" xyz="0 0 0" />
    </collision>
  </link>
  <joint name="joint3" type="revolute">
    <origin rpy="0 0 0" xyz="0.0535 -0.2845 0" />
    <parent link="link2" />
    <child link="link3" />
    <axis xyz="0 0 1" />
    <limit effort="30" lower="-3.927" upper="0.19198" velocity="3.14" />
    <dynamics damping="5" friction="1" />
  </joint>
  <link name="link4">
    <inertial>
      <origin rpy="0 0 0" xyz="0.06489 0.03122 0.00319" />
      <mass value="1.3169" />
      <inertia ixx="0.00144315" ixy="-0.000455133" ixz="0.000291878" iyy="0.0018275" iyz="0.000132545" izz="0.00231563" />
    </inertial>
    <visual>
      <geometry>
        <mesh filename="meshes/xarm5_1305/visual_glb/link4.glb" />
      </geometry>
      <origin rpy="0 0 0" xyz="0 0 0" />
      <material name="White" />
    </visual>
    <collision>
      <geometry>
        <mesh filename="meshes/xarm5_1305/collision/link4.obj" />
      </geometry>
      <origin rpy="0 0 0" xyz="0 0 0" />
    </collision>
  </link>
  <joint name="joint4" type="revolute">
    <origin rpy="0 0 0" xyz="0.0775 0.3425 0" />
    <parent link="link3" />
    <child link="link4" />
    <axis xyz="0 0 1" />
    <limit effort="20" lower="-1.69297" upper="3.141592653589793" velocity="3.14" />
    <dynamics damping="3" friction="1" />
  </joint>
  <link name="link5">
    <inertial>
      <origin rpy="0 0 0" xyz="0 -0.00677 -0.01098" />
      <mass value="0.17" />
      <inertia ixx="9.3e-05" ixy="-0.0" ixz="-0.0" iyy="5.87e-05" iyz="-3.6e-06" izz="0.000132" />
    </inertial>
    <visual>
      <geometry>
        <mesh filename="meshes/xarm5_1305/visual_glb/link5.glb" />
      </geometry>
      <origin rpy="0 0 0" xyz="0 0 0" />
      <material name="Silver" />
    </visual>
    <collision>
      <geometry>
        <mesh filename="meshes/xarm5_1305/collision/link5.obj" />
      </geometry>
      <origin rpy="0 0 0" xyz="0 0 0" />
    </collision>
  </link>
  <joint name="joint5" type="revolute">
    <origin rpy="-1.5708 0 0" xyz="0.076 0.097 0" />
    <parent link="link4" />
    <child link="link5" />
    <axis xyz="0 0 1" />
    <limit effort="20" lower="-6.283185307179586" upper="6.283185307179586" velocity="3.14" />
    <dynamics damping="3" friction="1" />
  </joint>
  <joint name="bio_gripper_g2_attach" type="fixed">
    <parent link="link5" />
    <child link="bio_gripper_g2_base_link" />
    <origin xyz="0.026044 -0.000867 -0.000697" rpy="0.00000000 0.00000000 -0.00702875" />
  </joint>
  <link name="bio_gripper_g2_base_link">
    <inertial>
      <origin rpy="0 0 0" xyz="0.016179 -2.3911E-05 0.023897" />
      <mass value="0.38837" />
      <inertia ixx="0.00088398" ixy="4.8665E-08" ixz="5.6276E-06" iyy="0.00018256" iyz="4.0828E-08" izz="0.00094673" />
    </inertial>
    <visual>
      <origin xyz="0 0 0" rpy="0 0 0" />
      <geometry>
        <mesh filename="../bio_gripper_g2/meshes/visual/visual_glb/link5/bio_gripper_g2_base.glb" />
      </geometry>
    </visual>
    <collision>
      <origin rpy="0 0 0" xyz="0 0 0" />
      <geometry>
        <mesh filename="../bio_gripper_g2/meshes/visual/link_base.stl" />
      </geometry>
    </collision>
  </link>
  <link name="bio_gripper_g2_left_finger">
    <inertial>
      <origin rpy="0 0 0" xyz="0.021846 -0.0276 0.011911" />
      <mass value="0.012105" />
      <inertia ixx="3.7322E-06" ixy="4.1705E-06" ixz="-4.0142E-06" iyy="1.744E-05" iyz="1.2237E-06" izz="1.7775E-05" />
    </inertial>
    <visual>
      <origin xyz="0 0 0" rpy="0 0 0" />
      <geometry>
        <mesh filename="../bio_gripper_g2/meshes/visual/visual_glb/link5/bio_gripper_g2_left_finger.glb" />
      </geometry>
    </visual>
    <collision>
      <origin rpy="0 0 0" xyz="0 0 0" />
      <geometry>
        <mesh filename="../bio_gripper_g2/meshes/visual/left_finger.stl" />
      </geometry>
    </collision>
  </link>
  <joint name="bio_gripper_g2_left_finger_joint" type="prismatic">
    <origin rpy="0 0 0" xyz="0.059 0 0.027" />
    <parent link="bio_gripper_g2_base_link" />
    <child link="bio_gripper_g2_left_finger" />
    <axis xyz="0 1 0" />
    <limit effort="2.0" lower="-0.0395" upper="0.0" velocity="0.1" />
    <mimic joint="bio_gripper_g2_right_finger_joint" multiplier="-1" offset="0" />
  </joint>
  <link name="bio_gripper_g2_right_finger">
    <inertial>
      <origin rpy="0 0 0" xyz="0.02037 0.027565 0.010274" />
      <mass value="0.012068" />
      <inertia ixx="4.1413E-06" ixy="-3.9682E-06" ixz="-4.5734E-06" iyy="1.6115E-05" iyz="-1.6711E-06" izz="1.6032E-05" />
    </inertial>
    <visual>
      <origin xyz="0 0 0" rpy="0 0 0" />
      <geometry>
        <mesh filename="../bio_gripper_g2/meshes/visual/visual_glb/link5/bio_gripper_g2_right_finger.glb" />
      </geometry>
    </visual>
    <collision>
      <origin rpy="0 0 0" xyz="0 0 0" />
      <geometry>
        <mesh filename="../bio_gripper_g2/meshes/visual/right_finger.stl" />
      </geometry>
    </collision>
  </link>
  <joint name="bio_gripper_g2_right_finger_joint" type="prismatic">
    <origin rpy="0 0 0" xyz="0.059 0 0.027" />
    <parent link="bio_gripper_g2_base_link" />
    <child link="bio_gripper_g2_right_finger" />
    <axis xyz="0 1 0" />
    <limit effort="2.0" lower="0" upper="0.0395" velocity="0.1" />
  </joint>
  <link name="bio_gripper_g2_tcp_link" />
  <joint name="bio_gripper_g2_tcp_joint" type="fixed">
    <origin rpy="0 0 0" xyz="0.135 0 0.055" />
    <parent link="bio_gripper_g2_base_link" />
    <child link="bio_gripper_g2_tcp_link" />
  </joint>
</robot>