<?xml version='1.0' encoding='utf-8'?>
<robot name="xarm6_1305_bio_gripper_movable_visual.glb">
  <material name="White">
    <color rgba="1.0 1.0 1.0 1.0" />
  </material>
  <material name="Silver">
    <color rgba="0.75 0.75 0.75 1.0" />
  </material>
  <link name="world" />
  <link name="link_base">
    <inertial>
      <origin xyz="0.0 0.0 0.09103" rpy="0 0 0" />
      <mass value="2.7" />
      <inertia ixx="0.00494875" ixy="-3.5e-06" ixz="1.25e-05" iyy="0.00494174" iyz="1.67e-06" izz="0.002219" />
    </inertial>
    <visual>
      <origin xyz="0 0 0" rpy="0 0 0" />
      <geometry>
        <mesh filename="meshes/xarm6_1305/visual_glb/link_base.glb" />
      </geometry>
    </visual>
    <collision>
      <origin xyz="0 0 0" rpy="0 0 0" />
      <geometry>
        <mesh filename="meshes/xarm6_1305/visual/link_base.stl" />
      </geometry>
    </collision>
  </link>
  <joint name="world_joint" type="fixed">
    <parent link="world" />
    <child link="link_base" />
    <origin xyz="0 0 0" rpy="0 0 0" />
  </joint>
  <link name="link1">
    <inertial>
      <origin xyz="0.00022 0.02951 -0.0124" rpy="0 0 0" />
      <mass value="2.3814" />
      <inertia ixx="0.0058562" ixy="-1.79e-05" ixz="3.55e-06" iyy="0.0050316" iyz="-0.000888336" izz="0.003536652" />
    </inertial>
    <visual>
      <origin xyz="0 0 0" rpy="0 0 0" />
      <geometry>
        <mesh filename="meshes/xarm6_1305/visual_glb/link1.glb" />
      </geometry>
    </visual>
    <collision>
      <origin xyz="0 0 0" rpy="0 0 0" />
      <geometry>
        <mesh filename="meshes/xarm6_1305/visual/link1.stl" />
      </geometry>
    </collision>
  </link>
  <joint name="joint1" type="revolute">
    <parent link="link_base" />
    <child link="link1" />
    <origin xyz="0 0 0.267" rpy="0 0 0" />
    <axis xyz="0 0 1" />
    <limit lower="-6.2832" upper="6.2832" effort="50.0" velocity="3.14" />
    <dynamics damping="1.0" friction="1.0" />
  </joint>
  <link name="link2">
    <inertial>
      <origin xyz="0.03881 -0.22783 0.03496" rpy="0 0 0" />
      <mass value="2.2675" />
      <inertia ixx="0.028315776" ixy="0.005" ixz="0.00066546" iyy="0.0058" iyz="-0.0045741" izz="0.0273447" />
    </inertial>
    <visual>
      <origin xyz="0 0 0" rpy="0 0 0" />
      <geometry>
        <mesh filename="meshes/xarm6_1305/visual_glb/link2.glb" />
      </geometry>
    </visual>
    <collision>
      <origin xyz="0 0 0" rpy="0 0 0" />
      <geometry>
        <mesh filename="meshes/xarm6_1305/visual/link2.stl" />
      </geometry>
    </collision>
  </link>
  <joint name="joint2" type="revolute">
    <parent link="link1" />
    <child link="link2" />
    <origin xyz="0 0 0" rpy="-1.5708 0 0" />
    <axis xyz="0 0 1" />
    <limit lower="-2.059" upper="2.0944" effort="50.0" velocity="3.14" />
    <dynamics damping="1.0" friction="1.0" />
  </joint>
  <link name="link3">
    <inertial>
      <origin xyz="0.07041 0.11631 0.0107" rpy="0 0 0" />
      <mass value="1.875" />
      <inertia ixx="0.0063483" ixy="-0.0015397" ixz="0.00096858" iyy="0.00379758" iyz="0.00186567" izz="0.00595768" />
    </inertial>
    <visual>
      <origin xyz="0 0 0" rpy="0 0 0" />
      <geometry>
        <mesh filename="meshes/xarm6_1305/visual_glb/link3.glb" />
      </geometry>
    </visual>
    <collision>
      <origin xyz="0 0 0" rpy="0 0 0" />
      <geometry>
        <mesh filename="meshes/xarm6_1305/visual/link3.stl" />
      </geometry>
    </collision>
  </link>
  <joint name="joint3" type="revolute">
    <parent link="link2" />
    <child link="link3" />
    <origin xyz="0.0535 -0.2845 0" rpy="0 0 0" />
    <axis xyz="0 0 1" />
    <limit lower="-3.927" upper="0.19198" effort="32.0" velocity="3.14" />
    <dynamics damping="1.0" friction="1.0" />
  </joint>
  <link name="link4">
    <inertial>
      <origin xyz="-0.00018 0.01798 -0.02291" rpy="0 0 0" />
      <mass value="1.3192" />
      <inertia ixx="0.004896" ixy="-6.925e-06" ixz="-1.418e-05" iyy="0.00445694" iyz="-0.00023186" izz="0.00134332" />
    </inertial>
    <visual>
      <origin xyz="0 0 0" rpy="0 0 0" />
      <geometry>
        <mesh filename="meshes/xarm6_1305/visual_glb/link4.glb" />
      </geometry>
    </visual>
    <collision>
      <origin xyz="0 0 0" rpy="0 0 0" />
      <geometry>
        <mesh filename="meshes/xarm6_1305/visual/link4.stl" />
      </geometry>
    </collision>
  </link>
  <joint name="joint4" type="revolute">
    <parent link="link3" />
    <child link="link4" />
    <origin xyz="0.0775 0.3425 0" rpy="-1.5708 0 0" />
    <axis xyz="0 0 1" />
    <limit lower="-6.2832" upper="6.2832" effort="32.0" velocity="3.14" />
    <dynamics damping="1.0" friction="1.0" />
  </joint>
  <link name="link5">
    <inertial>
      <origin xyz="0.0651 0.03096 0.00315" rpy="0 0 0" />
      <mass value="1.33854" />
      <inertia ixx="0.00146378" ixy="-0.000450624" ixz="0.000284306" iyy="0.00184192" iyz="0.000130866" izz="0.002333524" />
    </inertial>
    <visual>
      <origin xyz="0 0 0" rpy="0 0 0" />
      <geometry>
        <mesh filename="meshes/xarm6_1305/visual_glb/link5.glb" />
      </geometry>
    </visual>
    <collision>
      <origin xyz="0 0 0" rpy="0 0 0" />
      <geometry>
        <mesh filename="meshes/xarm6_1305/visual/link5.stl" />
      </geometry>
    </collision>
  </link>
  <joint name="joint5" type="revolute">
    <parent link="link4" />
    <child link="link5" />
    <origin xyz="0 0 0" rpy="1.5708 0 0" />
    <axis xyz="0 0 1" />
    <limit lower="-1.69297" upper="3.14159" effort="32.0" velocity="3.14" />
    <dynamics damping="1.0" friction="1.0" />
  </joint>
  <link name="link6">
    <inertial>
      <origin xyz="0 -0.00677 -0.01098" rpy="0 0 0" />
      <mass value="0.17" />
      <inertia ixx="9.3e-05" ixy="0.0" ixz="0.0" iyy="5.87e-05" iyz="-3.6e-06" izz="0.000132" />
    </inertial>
    <visual>
      <origin xyz="0 0 0" rpy="0 0 0" />
      <geometry>
        <mesh filename="meshes/xarm6_1305/visual_glb/link6.glb" />
      </geometry>
    </visual>
    <collision>
      <origin xyz="0 0 0" rpy="0 0 0" />
      <geometry>
        <mesh filename="meshes/xarm6_1305/visual/link6.stl" />
      </geometry>
    </collision>
  </link>
  <joint name="joint6" type="revolute">
    <parent link="link5" />
    <child link="link6" />
    <origin xyz="0.076 0.097 0" rpy="-1.5708 0 0" />
    <axis xyz="0 0 1" />
    <limit lower="-6.2832" upper="6.2832" effort="20.0" velocity="3.14" />
    <dynamics damping="1.0" friction="1.0" />
  </joint>
  <link name="link_eef" />
  <joint name="joint_eef" type="fixed">
    <parent link="link6" />
    <child link="link_eef" />
    <origin xyz="0 0 0" rpy="0 0 0" />
  </joint>
  <joint name="bio_gripper_attach" type="fixed">
    <parent link="link6" />
    <child link="bio_gripper_base_link" />
    <origin xyz="0 0 0" rpy="0 0 0" />
  </joint>
  <link name="bio_gripper_base_link">
    <inertial>
      <origin rpy="0 0 0" xyz="0.016179 -2.3911E-05 0.023897" />
      <mass value="0.38837" />
      <inertia ixx="0.00088398" ixy="4.8665E-08" ixz="5.6276E-06" iyy="0.00018256" iyz="4.0828E-08" izz="0.00094673" />
    </inertial>
    <visual>
      <origin xyz="0 0 0" rpy="3.14159265 0 0" />
      <geometry>
        <mesh filename="../bio_gripper/meshes/visual/visual_glb/link6/bio_gripper_base.glb" />
      </geometry>
    </visual>
    <collision>
      <origin rpy="0 0 0" xyz="0 0 0" />
      <geometry>
        <mesh filename="../bio_gripper/meshes/visual/link_base.stl" />
      </geometry>
    </collision>
  </link>
  <link name="bio_gripper_left_finger">
    <inertial>
      <origin rpy="0 0 0" xyz="0.021846 -0.0276 0.011911" />
      <mass value="0.012105" />
      <inertia ixx="3.7322E-06" ixy="4.1705E-06" ixz="-4.0142E-06" iyy="1.744E-05" iyz="1.2237E-06" izz="1.7775E-05" />
    </inertial>
    <visual>
      <origin xyz="0 0 0" rpy="0 0 0" />
      <geometry>
        <mesh filename="../bio_gripper/meshes/visual/visual_glb/link6/bio_left_finger.glb" />
      </geometry>
    </visual>
    <collision>
      <origin rpy="0 0 0" xyz="0 0 0" />
      <geometry>
        <mesh filename="../bio_gripper/meshes/visual/left_finger.stl" />
      </geometry>
    </collision>
  </link>
  <joint name="left_finger_joint" type="prismatic">
    <origin rpy="0 0 0" xyz="0.059 0 0.027" />
    <parent link="bio_gripper_base_link" />
    <child link="bio_gripper_left_finger" />
    <axis xyz="0 1 0" />
    <limit effort="2.0" lower="-0.04" upper="0.0" velocity="0.1" />
    <mimic joint="right_finger_joint" multiplier="-1" offset="0" />
  </joint>
  <link name="bio_gripper_right_finger">
    <inertial>
      <origin rpy="0 0 0" xyz="0.02037 0.027565 0.010274" />
      <mass value="0.012068" />
      <inertia ixx="4.1413E-06" ixy="-3.9682E-06" ixz="-4.5734E-06" iyy="1.6115E-05" iyz="-1.6711E-06" izz="1.6032E-05" />
    </inertial>
    <visual>
      <origin xyz="0 0 0" rpy="0 0 0" />
      <geometry>
        <mesh filename="../bio_gripper/meshes/visual/visual_glb/link6/bio_right_finger.glb" />
      </geometry>
    </visual>
    <collision>
      <origin rpy="0 0 0" xyz="0 0 0" />
      <geometry>
        <mesh filename="../bio_gripper/meshes/visual/right_finger.stl" />
      </geometry>
    </collision>
  </link>
  <joint name="right_finger_joint" type="prismatic">
    <origin rpy="0 0 0" xyz="0.059 0 0.027" />
    <parent link="bio_gripper_base_link" />
    <child link="bio_gripper_right_finger" />
    <axis xyz="0 1 0" />
    <limit effort="2.0" lower="0" upper="0.04" velocity="0.1" />
  </joint>
  <link name="link_tcp" />
  <joint name="joint_tcp" type="fixed">
    <origin rpy="0 0 0" xyz="0.135 0 0.055" />
    <parent link="bio_gripper_base_link" />
    <child link="link_tcp" />
  </joint>
</robot>